Workbook
Name AvanceTbl: Config!$B$6:$C$9
Name EstadoCambioList: Config!$G$13:$G$16
Name EstadoList: Config!$B$6:$B$9
Name EstadoNCList: Config!$E$13:$E$16
Name SeveridadList: Config!$B$13:$B$15
Name TableroList: Config!$J$5:$J$10

Sheet Resumen
B2: RESUMEN GENERAL — INTEGRACIÓN DE TABLEROS
B3: Consolidado automático. Fechas plan cargadas desde la carta Gantt del proveedor.
B5: Tablero | C5: Avance Global | D5: Estado General | E5: Plan Inicio | F5: Plan Fin Despacho | G5: Real Fin Despacho | H5: NC Abiertas | I5: Cambios Pend.
B6: TP | C6: =TP!$G$7 -> 0.11842105 | D6: =IF(C6>=1,"Completado",IF(C6>=0.99,"Por liberar",IF(C6>0,"En proceso","No iniciado"))) -> En proceso | E6: =TP!$G$10 -> 46202 | F6: =TP!$H$52 -> 46217 | G6: =TP!$J$55 -> 0 | H6: =COUNTIFS(NoConformidades!$C:$C,B6,NoConformidades!$H:$H,"<>Cerrada") -> 0 | I6: =COUNTIFS(ControlCambios!$C:$C,B6,ControlCambios!$G:$G,"Propuesto") -> 0
B7: T_G2 | C7: =T_G2!$G$7 -> 0.11842105 | D7: =IF(C7>=1,"Completado",IF(C7>=0.99,"Por liberar",IF(C7>0,"En proceso","No iniciado"))) -> En proceso | E7: =T_G2!$G$10 -> 46202 | F7: =T_G2!$H$52 -> 46217 | G7: =T_G2!$J$55 -> 0 | H7: =COUNTIFS(NoConformidades!$C:$C,B7,NoConformidades!$H:$H,"<>Cerrada") -> 0 | I7: =COUNTIFS(ControlCambios!$C:$C,B7,ControlCambios!$G:$G,"Propuesto") -> 0
B8: BUS_A | C8: =BUS_A!$G$7 -> 0.11842105 | D8: =IF(C8>=1,"Completado",IF(C8>=0.99,"Por liberar",IF(C8>0,"En proceso","No iniciado"))) -> En proceso | E8: =BUS_A!$G$10 -> 46202 | F8: =BUS_A!$H$52 -> 46217 | G8: =BUS_A!$J$55 -> 0 | H8: =COUNTIFS(NoConformidades!$C:$C,B8,NoConformidades!$H:$H,"<>Cerrada") -> 0 | I8: =COUNTIFS(ControlCambios!$C:$C,B8,ControlCambios!$G:$G,"Propuesto") -> 0
B9: BUS_B | C9: =BUS_B!$G$7 -> 0.11842105 | D9: =IF(C9>=1,"Completado",IF(C9>=0.99,"Por liberar",IF(C9>0,"En proceso","No iniciado"))) -> En proceso | E9: =BUS_B!$G$10 -> 46202 | F9: =BUS_B!$H$52 -> 46217 | G9: =BUS_B!$J$55 -> 0 | H9: =COUNTIFS(NoConformidades!$C:$C,B9,NoConformidades!$H:$H,"<>Cerrada") -> 0 | I9: =COUNTIFS(ControlCambios!$C:$C,B9,ControlCambios!$G:$G,"Propuesto") -> 0
B10: CLIMA_A | C10: =CLIMA_A!$G$7 -> 0.20512821 | D10: =IF(C10>=1,"Completado",IF(C10>=0.99,"Por liberar",IF(C10>0,"En proceso","No iniciado"))) -> En proceso | E10: =CLIMA_A!$G$10 -> 46202 | F10: =CLIMA_A!$H$52 -> 46217 | G10: =CLIMA_A!$J$55 -> 0 | H10: =COUNTIFS(NoConformidades!$C:$C,B10,NoConformidades!$H:$H,"<>Cerrada") -> 0 | I10: =COUNTIFS(ControlCambios!$C:$C,B10,ControlCambios!$G:$G,"Propuesto") -> 0
B11: CLIMA_B | C11: =CLIMA_B!$G$7 -> 0.20512821 | D11: =IF(C11>=1,"Completado",IF(C11>=0.99,"Por liberar",IF(C11>0,"En proceso","No iniciado"))) -> En proceso | E11: =CLIMA_B!$G$10 -> 46202 | F11: =CLIMA_B!$H$52 -> 46217 | G11: =CLIMA_B!$J$55 -> 0 | H11: =COUNTIFS(NoConformidades!$C:$C,B11,NoConformidades!$H:$H,"<>Cerrada") -> 0 | I11: =COUNTIFS(ControlCambios!$C:$C,B11,ControlCambios!$G:$G,"Propuesto") -> 0
B12: PROMEDIO / TOTAL | C12: =AVERAGE(C6:C11) -> 0.14732344 | H12: =SUM(H6:H11) -> 0 | I12: =SUM(I6:I11) -> 0
B15: Leyenda estados (sub-hitos):
B16: Pendiente = 0% | C16: En proceso = 50% | D16: Completado = 100% | E16: N/A = excluido

Sheet Gantt Plan
B2: CARTA GANTT — PLAN DE FABRICACIÓN (PROVEEDOR)
C3: L | D3: M | E3: M | F3: J | G3: V | H3: S | I3: D | J3: L | K3: M | L3: M | M3: J | N3: V | O3: S | P3: D | Q3: L | R3: M | S3: M | T3: J | U3: V | V3: S | W3: D | X3: L | Y3: M | Z3: M | AA3: J | AB3: V | AC3: S | AD3: D | AE3: L | AF3: M | AG3: M | AH3: J | AI3: V | AJ3: S | AK3: D | AL3: L | AM3: M | AN3: M | AO3: J | AP3: V
B4: Tablero / Hito | C4: 22-06 | D4: 23-06 | E4: 24-06 | F4: 25-06 | G4: 26-06 | H4: 27-06 | I4: 28-06 | J4: 29-06 | K4: 30-06 | L4: 01-07 | M4: 02-07 | N4: 03-07 | O4: 04-07 | P4: 05-07 | Q4: 06-07 | R4: 07-07 | S4: 08-07 | T4: 09-07 | U4: 10-07 | V4: 11-07 | W4: 12-07 | X4: 13-07 | Y4: 14-07 | Z4: 15-07 | AA4: 16-07 | AB4: 17-07 | AC4: 18-07 | AD4: 19-07 | AE4: 20-07 | AF4: 21-07 | AG4: 22-07 | AH4: 23-07 | AI4: 24-07 | AJ4: 25-07 | AK4: 26-07 | AL4: 27-07 | AM4: 28-07 | AN4: 29-07 | AO4: 30-07 | AP4: 31-07
B5: TP
B6: 1. Armado de Tablero
B7: 2. Montaje de protecciones
B8: 3. Fabricación y montaje de barras
B9: 4. Alambrado del tablero
B10: 5. Rotulación
B11: 6. Pruebas FAT
B12: 7. Embalaje
B13: 8. Despacho
B14: BUS_A
B15: 1. Armado de Tablero
B16: 2. Montaje de protecciones
... B60: Barras = ventana plan del proveedor. Gris = fin de semana.

Sheet TP
B2: SEGUIMIENTO DE INTEGRACIÓN — TABLERO TP
B4: Proyecto: | F4: TAG: | G4: TP | I4: Rev.:
B5: Fabricante: | F5: OC/Contrato: | I5: Actualizado: | J5: 46230
B7: AVANCE GLOBAL DEL TABLERO | G7: =IFERROR(($D10*$F10+$D16*$F16+$D23*$F23+$D30*$F30+$D37*$F37+$D43*$F43+$D47*$F47+$D52*$F52)/($D10+$D16+$D23+$D30+$D37+$D43+$D47+$D52),0) -> 0.11842105
B9: # | C9: Hito / Sub-actividad | D9: Peso | E9: Estado | F9: Avance | G9: Plan Inicio | H9: Plan Fin | I9: Real Inicio | J9: Real Fin | K9: Responsable | L9: Observaciones
C10: 1. Armado de Tablero | D10: =SUMIF($E11:$E15,"<>N/A",$D11:$D15) -> 5 | F10: {=IFERROR(SUMPRODUCT(($E11:$E15<>"N/A")*$D11:$D15,IF($E11:$E15="N/A",0,$F11:$F15))/$D10,0)} -> 0.4 | G10: 46202 | H10: 46205
B11: 1.1 | C11: Recepción y verificación de envolvente (dimensiones, IP/IK, RAL) | D11: 1 | E11: Completado | F11: =IF($E11="N/A","",VLOOKUP($E11,AvanceTbl,2,FALSE())) -> 1 | K11: CSE
B12: 1.2 | C12: Ensamble de estructura y paneles del gabinete | D12: 1 | E12: Completado | F12: =IF($E12="N/A","",VLOOKUP($E12,AvanceTbl,2,FALSE())) -> 1 | K12: CMF
B13: 1.3 | C13: Montaje de perfilería DIN y placas de montaje | D13: 1 | E13: Pendiente | F13: =IF($E13="N/A","",VLOOKUP($E13,AvanceTbl,2,FALSE())) -> 0 | K13: CMF
B14: 1.4 | C14: Instalación de puertas, bisagras y cerraduras | D14: 1 | E14: Pendiente | F14: =IF($E14="N/A","",VLOOKUP($E14,AvanceTbl,2,FALSE())) -> 0 | K14: CMF
B15: 1.5 | C15: Fijación de canaletas y sistema de cableado | D15: 1 | E15: Pendiente | F15: =IF($E15="N/A","",VLOOKUP($E15,AvanceTbl,2,FALSE())) -> 0 | K15: CSE
C16: 2. Montaje de protecciones | D16: =SUMIF($E17:$E22,"<>N/A",$D17:$D22) -> 5 | F16: {=IFERROR(SUMPRODUCT(($E17:$E22<>"N/A")*$D17:$D22,IF($E17:$E22="N/A",0,$F17:$F22))/$D16,0)} -> 0.4 | G16: 46205 | H16: 46206
B17: 2.1 | C17: Verificación de aparatos vs. lista de materiales (marca/In/Icu) | D17: 1 | E17: Completado | F17: =IF($E17="N/A","",VLOOKUP($E17,AvanceTbl,2,FALSE())) -> 1 | K17: CSE
B18: 2.2 | C18: Montaje de interruptor principal | D18: 1 | E18: Completado | F18: =IF($E18="N/A","",VLOOKUP($E18,AvanceTbl,2,FALSE())) -> 1 | K18: CMF
B19: 2.3 | C19: Montaje de protecciones de derivación | D19: 1 | E19: Pendiente | F19: =IF($E19="N/A","",VLOOKUP($E19,AvanceTbl,2,FALSE())) -> 0 | K19: CMF
B20: 2.4 | C20: Montaje de diferenciales / protecciones auxiliares | D20: 1 | E20: N/A | F20: =IF($E20="N/A","",VLOOKUP($E20,AvanceTbl,2,FALSE())) | K20: CMF
B21: 2.5 | C21: Instalación de instrumentación (medidores, TC, relés) | D21: 1 | E21: Pendiente | F21: =IF($E21="N/A","",VLOOKUP($E21,AvanceTbl,2,FALSE())) -> 0 | K21: CMF
B22: 2.6 | C22: Fijación y torque de aparatos según layout | D22: 1 | E22: Pendiente | F22: =IF($E22="N/A","",VLOOKUP($E22,AvanceTbl,2,FALSE())) -> 0 | K22: CMF
C23: 3. Fabricación y montaje de barras | D23: =SUMIF($E24:$E29,"<>N/A",$D24:$D29) -> 6 | F23: {=IFERROR(SUMPRODUCT(($E24:$E29<>"N/A")*$D24:$D29,IF($E24:$E29="N/A",0,$F24:$F29))/$D23,0)} -> 0.083333333 | G23: 46205 | H23: 46206
B24: 3.1 | C24: Corte y conformado de barras (fases, N) | D24: 1 | E24: En proceso | F24: =IF($E24="N/A","",VLOOKUP($E24,AvanceTbl,2,FALSE())) -> 0.5 | K24: CMF
B25: 3.2 | C25: Perforado y tratamiento de superficie / aislamiento | D25: 1 | E25: Pendiente | F25: =IF($E25="N/A","",VLOOKUP($E25,AvanceTbl,2,FALSE())) -> 0 | K25: CMF
B26: 3.3 | C26: Montaje de aisladores y soportes de barra | D26: 1 | E26: Pendiente | F26: =IF($E26="N/A","",VLOOKUP($E26,AvanceTbl,2,FALSE())) -> 0 | K26: CMF
B27: 3.4 | C27: Instalación de barras principales con torque especificado | D27: 1 | E27: Pendiente | F27: =IF($E27="N/A","",VLOOKUP($E27,AvanceTbl,2,FALSE())) -> 0 | K27: CMF
B28: 3.5 | C28: Montaje de barra de tierra (PE) y neutro (N) | D28: 1 | E28: Pendiente | F28: =IF($E28="N/A","",VLOOKUP($E28,AvanceTbl,2,FALSE())) -> 0 | K28: CMF
B29: 3.6 | C29: Conexión de derivaciones a protecciones | D29: 1 | E29: Pendiente | F29: =IF($E29="N/A","",VLOOKUP($E29,AvanceTbl,2,FALSE())) -> 0 | K29: CMF
C30: 4. Alambrado del tablero | D30: =SUMIF($E31:$E36,"<>N/A",$D31:$D36) -> 6 | F30: {=IFERROR(SUMPRODUCT(($E31:$E36<>"N/A")*$D31:$D36,IF($E31:$E36="N/A",0,$F31:$F36))/$D30,0)} -> 0 | G30: 46208 | H30: 46212
B31: 4.1 | C31: Alambrado de circuito de fuerza | D31: 1 | E31: Pendiente | F31: =IF($E31="N/A","",VLOOKUP($E31,AvanceTbl,2,FALSE())) -> 0 | K31: CMF
B32: 4.2 | C32: Alambrado de circuito de control / mando | D32: 1 | E32: Pendiente | F32: =IF($E32="N/A","",VLOOKUP($E32,AvanceTbl,2,FALSE())) -> 0 | K32: CMF
B33: 4.3 | C33: Conexionado de instrumentación y señalización | D33: 1 | E33: Pendiente | F33: =IF($E33="N/A","",VLOOKUP($E33,AvanceTbl,2,FALSE())) -> 0 | K33: CMF
B34: 4.4 | C34: Montaje de punteras/terminales y apriete con torque | D34: 1 | E34: Pendiente | F34: =IF($E34="N/A","",VLOOKUP($E34,AvanceTbl,2,FALSE())) -> 0 | K34: CMF
B35: 4.5 | C35: Peinado y ordenamiento de mazos de cable | D35: 1 | E35: Pendiente | F35: =IF($E35="N/A","",VLOOKUP($E35,AvanceTbl,2,FALSE())) -> 0 | K35: CMF
B36: 4.6 | C36: Conexión de barra PE a partes metálicas accesibles | D36: 1 | E36: Pendiente | F36: =IF($E36="N/A","",VLOOKUP($E36,AvanceTbl,2,FALSE())) -> 0 | K36: CMF
C37: 5. Rotulación | D37: =SUMIF($E38:$E42,"<>N/A",$D38:$D42) -> 5 | F37: {=IFERROR(SUMPRODUCT(($E38:$E42<>"N/A")*$D38:$D42,IF($E38:$E42="N/A",0,$F38:$F42))/$D37,0)} -> 0 | G37: 46213 | H37: 46213
B38: 5.1 | C38: Etiquetado de conductores en ambos extremos | D38: 1 | E38: Pendiente | F38: =IF($E38="N/A","",VLOOKUP($E38,AvanceTbl,2,FALSE())) -> 0 | K38: CMF
B39: 5.2 | C39: Rotulado de aparatos y bornes según planos | D39: 1 | E39: Pendiente | F39: =IF($E39="N/A","",VLOOKUP($E39,AvanceTbl,2,FALSE())) -> 0 | K39: CMF
B40: 5.3 | C40: Instalación de placa de características (nameplate) | D40: 1 | E40: Pendiente | F40: =IF($E40="N/A","",VLOOKUP($E40,AvanceTbl,2,FALSE())) -> 0 | K40: CMF
B41: 5.4 | C41: Rótulos de advertencia y seguridad | D41: 1 | E41: Pendiente | F41: =IF($E41="N/A","",VLOOKUP($E41,AvanceTbl,2,FALSE())) -> 0 | K41: CMF
B42: 5.5 | C42: Verificación de coincidencia rótulos vs. esquema | D42: 1 | E42: Pendiente | F42: =IF($E42="N/A","",VLOOKUP($E42,AvanceTbl,2,FALSE())) -> 0 | K42: CSE
C43: 6. Pruebas FAT | D43: =SUMIF($E44:$E46,"<>N/A",$D44:$D46) -> 3 | F43: {=IFERROR(SUMPRODUCT(($E44:$E46<>"N/A")*$D44:$D46,IF($E44:$E46="N/A",0,$F44:$F46))/$D43,0)} -> 0 | G43: 46213 | H43: 46213
B44: 6.1 | C44: Ejecución de protocolo FAT (según alcance definido) | D44: 1 | E44: Pendiente | F44: =IF($E44="N/A","",VLOOKUP($E44,AvanceTbl,2,FALSE())) -> 0 | K44: CMF
...

Sheet T_G2
B2: SEGUIMIENTO DE INTEGRACIÓN — TABLERO T_G2
B4: Proyecto: | F4: TAG: | G4: T_G2 | I4: Rev.:
B5: Fabricante: | F5: C.Costo | G5: IN-17248 | I5: Actualizado: | J5: 46230
B7: AVANCE GLOBAL DEL TABLERO | G7: =IFERROR(($D10*$F10+$D16*$F16+$D23*$F23+$D30*$F30+$D37*$F37+$D43*$F43+$D47*$F47+$D52*$F52)/($D10+$D16+$D23+$D30+$D37+$D43+$D47+$D52),0) -> 0.11842105
B9: # | C9: Hito / Sub-actividad | D9: Peso | E9: Estado | F9: Avance | G9: Plan Inicio | H9: Plan Fin | I9: Real Inicio | J9: Real Fin | K9: Responsable | L9: Observaciones
C10: 1. Armado de Tablero | D10: =SUMIF($E11:$E15,"<>N/A",$D11:$D15) -> 5 | F10: {=IFERROR(SUMPRODUCT(($E11:$E15<>"N/A")*$D11:$D15,IF($E11:$E15="N/A",0,$F11:$F15))/$D10,0)} -> 0.4 | G10: 46202 | H10: 46205
B11: 1.1 | C11: Recepción y verificación de envolvente (dimensiones, IP/IK, RAL) | D11: 1 | E11: Completado | F11: =IF($E11="N/A","",VLOOKUP($E11,AvanceTbl,2,FALSE())) -> 1 | K11: CSE
B12: 1.2 | C12: Ensamble de estructura y paneles del gabinete | D12: 1 | E12: Completado | F12: =IF($E12="N/A","",VLOOKUP($E12,AvanceTbl,2,FALSE())) -> 1 | K12: CMF
B13: 1.3 | C13: Montaje de perfilería DIN y placas de montaje | D13: 1 | E13: Pendiente | F13: =IF($E13="N/A","",VLOOKUP($E13,AvanceTbl,2,FALSE())) -> 0 | K13: CMF
B14: 1.4 | C14: Instalación de puertas, bisagras y cerraduras | D14: 1 | E14: Pendiente | F14: =IF($E14="N/A","",VLOOKUP($E14,AvanceTbl,2,FALSE())) -> 0 | K14: CMF
B15: 1.5 | C15: Fijación de canaletas y sistema de cableado | D15: 1 | E15: Pendiente | F15: =IF($E15="N/A","",VLOOKUP($E15,AvanceTbl,2,FALSE())) -> 0 | K15: CSE
C16: 2. Montaje de protecciones | D16: =SUMIF($E17:$E22,"<>N/A",$D17:$D22) -> 5 | F16: {=IFERROR(SUMPRODUCT(($E17:$E22<>"N/A")*$D17:$D22,IF($E17:$E22="N/A",0,$F17:$F22))/$D16,0)} -> 0.4 | G16: 46205 | H16: 46206
B17: 2.1 | C17: Verificación de aparatos vs. lista de materiales (marca/In/Icu) | D17: 1 | E17: Completado | F17: =IF($E17="N/A","",VLOOKUP($E17,AvanceTbl,2,FALSE())) -> 1 | K17: CSE
B18: 2.2 | C18: Montaje de interruptor principal | D18: 1 | E18: Completado | F18: =IF($E18="N/A","",VLOOKUP($E18,AvanceTbl,2,FALSE())) -> 1 | K18: CMF
B19: 2.3 | C19: Montaje de protecciones de derivación | D19: 1 | E19: Pendiente | F19: =IF($E19="N/A","",VLOOKUP($E19,AvanceTbl,2,FALSE())) -> 0 | K19: CMF
B20: 2.4 | C20: Montaje de diferenciales / protecciones auxiliares | D20: 1 | E20: N/A | F20: =IF($E20="N/A","",VLOOKUP($E20,AvanceTbl,2,FALSE())) | K20: CMF
B21: 2.5 | C21: Instalación de instrumentación (medidores, TC, relés) | D21: 1 | E21: Pendiente | F21: =IF($E21="N/A","",VLOOKUP($E21,AvanceTbl,2,FALSE())) -> 0 | K21: CMF
B22: 2.6 | C22: Fijación y torque de aparatos según layout | D22: 1 | E22: Pendiente | F22: =IF($E22="N/A","",VLOOKUP($E22,AvanceTbl,2,FALSE())) -> 0 | K22: CMF
C23: 3. Fabricación y montaje de barras | D23: =SUMIF($E24:$E29,"<>N/A",$D24:$D29) -> 6 | F23: {=IFERROR(SUMPRODUCT(($E24:$E29<>"N/A")*$D24:$D29,IF($E24:$E29="N/A",0,$F24:$F29))/$D23,0)} -> 0.083333333 | G23: 46205 | H23: 46206
B24: 3.1 | C24: Corte y conformado de barras (fases, N) | D24: 1 | E24: En proceso | F24: =IF($E24="N/A","",VLOOKUP($E24,AvanceTbl,2,FALSE())) -> 0.5 | K24: CMF
B25: 3.2 | C25: Perforado y tratamiento de superficie / aislamiento | D25: 1 | E25: Pendiente | F25: =IF($E25="N/A","",VLOOKUP($E25,AvanceTbl,2,FALSE())) -> 0 | K25: CMF
B26: 3.3 | C26: Montaje de aisladores y soportes de barra | D26: 1 | E26: Pendiente | F26: =IF($E26="N/A","",VLOOKUP($E26,AvanceTbl,2,FALSE())) -> 0 | K26: CMF
B27: 3.4 | C27: Instalación de barras principales con torque especificado | D27: 1 | E27: Pendiente | F27: =IF($E27="N/A","",VLOOKUP($E27,AvanceTbl,2,FALSE())) -> 0 | K27: CMF
B28: 3.5 | C28: Montaje de barra de tierra (PE) y neutro (N) | D28: 1 | E28: Pendiente | F28: =IF($E28="N/A","",VLOOKUP($E28,AvanceTbl,2,FALSE())) -> 0 | K28: CMF
B29: 3.6 | C29: Conexión de derivaciones a protecciones | D29: 1 | E29: Pendiente | F29: =IF($E29="N/A","",VLOOKUP($E29,AvanceTbl,2,FALSE())) -> 0 | K29: CMF
C30: 4. Alambrado del tablero | D30: =SUMIF($E31:$E36,"<>N/A",$D31:$D36) -> 6 | F30: {=IFERROR(SUMPRODUCT(($E31:$E36<>"N/A")*$D31:$D36,IF($E31:$E36="N/A",0,$F31:$F36))/$D30,0)} -> 0 | G30: 46208 | H30: 46212
B31: 4.1 | C31: Alambrado de circuito de fuerza | D31: 1 | E31: Pendiente | F31: =IF($E31="N/A","",VLOOKUP($E31,AvanceTbl,2,FALSE())) -> 0 | K31: CMF
B32: 4.2 | C32: Alambrado de circuito de control / mando | D32: 1 | E32: Pendiente | F32: =IF($E32="N/A","",VLOOKUP($E32,AvanceTbl,2,FALSE())) -> 0 | K32: CMF
B33: 4.3 | C33: Conexionado de instrumentación y señalización | D33: 1 | E33: Pendiente | F33: =IF($E33="N/A","",VLOOKUP($E33,AvanceTbl,2,FALSE())) -> 0 | K33: CMF
B34: 4.4 | C34: Montaje de punteras/terminales y apriete con torque | D34: 1 | E34: Pendiente | F34: =IF($E34="N/A","",VLOOKUP($E34,AvanceTbl,2,FALSE())) -> 0 | K34: CMF
B35: 4.5 | C35: Peinado y ordenamiento de mazos de cable | D35: 1 | E35: Pendiente | F35: =IF($E35="N/A","",VLOOKUP($E35,AvanceTbl,2,FALSE())) -> 0 | K35: CMF
B36: 4.6 | C36: Conexión de barra PE a partes metálicas accesibles | D36: 1 | E36: Pendiente | F36: =IF($E36="N/A","",VLOOKUP($E36,AvanceTbl,2,FALSE())) -> 0 | K36: CMF
C37: 5. Rotulación | D37: =SUMIF($E38:$E42,"<>N/A",$D38:$D42) -> 5 | F37: {=IFERROR(SUMPRODUCT(($E38:$E42<>"N/A")*$D38:$D42,IF($E38:$E42="N/A",0,$F38:$F42))/$D37,0)} -> 0 | G37: 46213 | H37: 46213
B38: 5.1 | C38: Etiquetado de conductores en ambos extremos | D38: 1 | E38: Pendiente | F38: =IF($E38="N/A","",VLOOKUP($E38,AvanceTbl,2,FALSE())) -> 0 | K38: CMF
B39: 5.2 | C39: Rotulado de aparatos y bornes según planos | D39: 1 | E39: Pendiente | F39: =IF($E39="N/A","",VLOOKUP($E39,AvanceTbl,2,FALSE())) -> 0 | K39: CMF
B40: 5.3 | C40: Instalación de placa de características (nameplate) | D40: 1 | E40: Pendiente | F40: =IF($E40="N/A","",VLOOKUP($E40,AvanceTbl,2,FALSE())) -> 0 | K40: CMF
B41: 5.4 | C41: Rótulos de advertencia y seguridad | D41: 1 | E41: Pendiente | F41: =IF($E41="N/A","",VLOOKUP($E41,AvanceTbl,2,FALSE())) -> 0 | K41: CMF
B42: 5.5 | C42: Verificación de coincidencia rótulos vs. esquema | D42: 1 | E42: Pendiente | F42: =IF($E42="N/A","",VLOOKUP($E42,AvanceTbl,2,FALSE())) -> 0 | K42: CSE
C43: 6. Pruebas FAT | D43: =SUMIF($E44:$E46,"<>N/A",$D44:$D46) -> 3 | F43: {=IFERROR(SUMPRODUCT(($E44:$E46<>"N/A")*$D44:$D46,IF($E44:$E46="N/A",0,$F44:$F46))/$D43,0)} -> 0 | G43: 46213 | H43: 46213
B44: 6.1 | C44: Ejecución de protocolo FAT (según alcance definido) | D44: 1 | E44: Pendiente | F44: =IF($E44="N/A","",VLOOKUP($E44,AvanceTbl,2,FALSE())) -> 0 | K44: CMF
...

Sheet BUS_A
B2: SEGUIMIENTO DE INTEGRACIÓN — TABLERO BUS_A
B4: Proyecto: | F4: TAG: | G4: BUS_A | I4: Rev.:
B5: Fabricante: | F5: OC/Contrato: | I5: Actualizado:
B7: AVANCE GLOBAL DEL TABLERO | G7: =IFERROR(($D10*$F10+$D16*$F16+$D23*$F23+$D30*$F30+$D37*$F37+$D43*$F43+$D47*$F47+$D52*$F52)/($D10+$D16+$D23+$D30+$D37+$D43+$D47+$D52),0) -> 0.11842105
B9: # | C9: Hito / Sub-actividad | D9: Peso | E9: Estado | F9: Avance | G9: Plan Inicio | H9: Plan Fin | I9: Real Inicio | J9: Real Fin | K9: Responsable | L9: Observaciones
C10: 1. Armado de Tablero | D10: =SUMIF($E11:$E15,"<>N/A",$D11:$D15) -> 5 | F10: {=IFERROR(SUMPRODUCT(($E11:$E15<>"N/A")*$D11:$D15,IF($E11:$E15="N/A",0,$F11:$F15))/$D10,0)} -> 0.4 | G10: 46202 | H10: 46205
B11: 1.1 | C11: Recepción y verificación de envolvente (dimensiones, IP/IK, RAL) | D11: 1 | E11: Completado | F11: =IF($E11="N/A","",VLOOKUP($E11,AvanceTbl,2,FALSE())) -> 1 | K11: CSE
B12: 1.2 | C12: Ensamble de estructura y paneles del gabinete | D12: 1 | E12: Completado | F12: =IF($E12="N/A","",VLOOKUP($E12,AvanceTbl,2,FALSE())) -> 1 | K12: CMF
B13: 1.3 | C13: Montaje de perfilería DIN y placas de montaje | D13: 1 | E13: Pendiente | F13: =IF($E13="N/A","",VLOOKUP($E13,AvanceTbl,2,FALSE())) -> 0 | K13: CMF
B14: 1.4 | C14: Instalación de puertas, bisagras y cerraduras | D14: 1 | E14: Pendiente | F14: =IF($E14="N/A","",VLOOKUP($E14,AvanceTbl,2,FALSE())) -> 0 | K14: CMF
B15: 1.5 | C15: Fijación de canaletas y sistema de cableado | D15: 1 | E15: Pendiente | F15: =IF($E15="N/A","",VLOOKUP($E15,AvanceTbl,2,FALSE())) -> 0 | K15: CSE
C16: 2. Montaje de protecciones | D16: =SUMIF($E17:$E22,"<>N/A",$D17:$D22) -> 5 | F16: {=IFERROR(SUMPRODUCT(($E17:$E22<>"N/A")*$D17:$D22,IF($E17:$E22="N/A",0,$F17:$F22))/$D16,0)} -> 0.4 | G16: 46208 | H16: 46213
B17: 2.1 | C17: Verificación de aparatos vs. lista de materiales (marca/In/Icu) | D17: 1 | E17: Completado | F17: =IF($E17="N/A","",VLOOKUP($E17,AvanceTbl,2,FALSE())) -> 1 | K17: CSE
B18: 2.2 | C18: Montaje de interruptor principal | D18: 1 | E18: Completado | F18: =IF($E18="N/A","",VLOOKUP($E18,AvanceTbl,2,FALSE())) -> 1 | K18: CMF
B19: 2.3 | C19: Montaje de protecciones de derivación | D19: 1 | E19: Pendiente | F19: =IF($E19="N/A","",VLOOKUP($E19,AvanceTbl,2,FALSE())) -> 0 | K19: CMF
B20: 2.4 | C20: Montaje de diferenciales / protecciones auxiliares | D20: 1 | E20: N/A | F20: =IF($E20="N/A","",VLOOKUP($E20,AvanceTbl,2,FALSE())) | K20: CMF
B21: 2.5 | C21: Instalación de instrumentación (medidores, TC, relés) | D21: 1 | E21: Pendiente | F21: =IF($E21="N/A","",VLOOKUP($E21,AvanceTbl,2,FALSE())) -> 0 | K21: CMF
B22: 2.6 | C22: Fijación y torque de aparatos según layout | D22: 1 | E22: Pendiente | F22: =IF($E22="N/A","",VLOOKUP($E22,AvanceTbl,2,FALSE())) -> 0 | K22: CMF
C23: 3. Fabricación y montaje de barras | D23: =SUMIF($E24:$E29,"<>N/A",$D24:$D29) -> 6 | F23: {=IFERROR(SUMPRODUCT(($E24:$E29<>"N/A")*$D24:$D29,IF($E24:$E29="N/A",0,$F24:$F29))/$D23,0)} -> 0.083333333 | G23: 46208 | H23: 46213
B24: 3.1 | C24: Corte y conformado de barras (fases, N) | D24: 1 | E24: En proceso | F24: =IF($E24="N/A","",VLOOKUP($E24,AvanceTbl,2,FALSE())) -> 0.5 | K24: CMF
B25: 3.2 | C25: Perforado y tratamiento de superficie / aislamiento | D25: 1 | E25: Pendiente | F25: =IF($E25="N/A","",VLOOKUP($E25,AvanceTbl,2,FALSE())) -> 0 | K25: CMF
B26: 3.3 | C26: Montaje de aisladores y soportes de barra | D26: 1 | E26: Pendiente | F26: =IF($E26="N/A","",VLOOKUP($E26,AvanceTbl,2,FALSE())) -> 0 | K26: CMF
B27: 3.4 | C27: Instalación de barras principales con torque especificado | D27: 1 | E27: Pendiente | F27: =IF($E27="N/A","",VLOOKUP($E27,AvanceTbl,2,FALSE())) -> 0 | K27: CMF
B28: 3.5 | C28: Montaje de barra de tierra (PE) y neutro (N) | D28: 1 | E28: Pendiente | F28: =IF($E28="N/A","",VLOOKUP($E28,AvanceTbl,2,FALSE())) -> 0 | K28: CMF
B29: 3.6 | C29: Conexión de derivaciones a protecciones | D29: 1 | E29: Pendiente | F29: =IF($E29="N/A","",VLOOKUP($E29,AvanceTbl,2,FALSE())) -> 0 | K29: CMF
C30: 4. Alambrado del tablero | D30: =SUMIF($E31:$E36,"<>N/A",$D31:$D36) -> 6 | F30: {=IFERROR(SUMPRODUCT(($E31:$E36<>"N/A")*$D31:$D36,IF($E31:$E36="N/A",0,$F31:$F36))/$D30,0)} -> 0 | G30: 46212 | H30: 46213
B31: 4.1 | C31: Alambrado de circuito de fuerza | D31: 1 | E31: Pendiente | F31: =IF($E31="N/A","",VLOOKUP($E31,AvanceTbl,2,FALSE())) -> 0 | K31: CMF
B32: 4.2 | C32: Alambrado de circuito de control / mando | D32: 1 | E32: Pendiente | F32: =IF($E32="N/A","",VLOOKUP($E32,AvanceTbl,2,FALSE())) -> 0 | K32: CMF
B33: 4.3 | C33: Conexionado de instrumentación y señalización | D33: 1 | E33: Pendiente | F33: =IF($E33="N/A","",VLOOKUP($E33,AvanceTbl,2,FALSE())) -> 0 | K33: CMF
B34: 4.4 | C34: Montaje de punteras/terminales y apriete con torque | D34: 1 | E34: Pendiente | F34: =IF($E34="N/A","",VLOOKUP($E34,AvanceTbl,2,FALSE())) -> 0 | K34: CMF
B35: 4.5 | C35: Peinado y ordenamiento de mazos de cable | D35: 1 | E35: Pendiente | F35: =IF($E35="N/A","",VLOOKUP($E35,AvanceTbl,2,FALSE())) -> 0 | K35: CMF
B36: 4.6 | C36: Conexión de barra PE a partes metálicas accesibles | D36: 1 | E36: Pendiente | F36: =IF($E36="N/A","",VLOOKUP($E36,AvanceTbl,2,FALSE())) -> 0 | K36: CMF
C37: 5. Rotulación | D37: =SUMIF($E38:$E42,"<>N/A",$D38:$D42) -> 5 | F37: {=IFERROR(SUMPRODUCT(($E38:$E42<>"N/A")*$D38:$D42,IF($E38:$E42="N/A",0,$F38:$F42))/$D37,0)} -> 0 | G37: 46217 | H37: 46217
B38: 5.1 | C38: Etiquetado de conductores en ambos extremos | D38: 1 | E38: Pendiente | F38: =IF($E38="N/A","",VLOOKUP($E38,AvanceTbl,2,FALSE())) -> 0 | K38: CMF
B39: 5.2 | C39: Rotulado de aparatos y bornes según planos | D39: 1 | E39: Pendiente | F39: =IF($E39="N/A","",VLOOKUP($E39,AvanceTbl,2,FALSE())) -> 0 | K39: CMF
B40: 5.3 | C40: Instalación de placa de características (nameplate) | D40: 1 | E40: Pendiente | F40: =IF($E40="N/A","",VLOOKUP($E40,AvanceTbl,2,FALSE())) -> 0 | K40: CMF
B41: 5.4 | C41: Rótulos de advertencia y seguridad | D41: 1 | E41: Pendiente | F41: =IF($E41="N/A","",VLOOKUP($E41,AvanceTbl,2,FALSE())) -> 0 | K41: CMF
B42: 5.5 | C42: Verificación de coincidencia rótulos vs. esquema | D42: 1 | E42: Pendiente | F42: =IF($E42="N/A","",VLOOKUP($E42,AvanceTbl,2,FALSE())) -> 0 | K42: CSE
C43: 6. Pruebas FAT | D43: =SUMIF($E44:$E46,"<>N/A",$D44:$D46) -> 3 | F43: {=IFERROR(SUMPRODUCT(($E44:$E46<>"N/A")*$D44:$D46,IF($E44:$E46="N/A",0,$F44:$F46))/$D43,0)} -> 0 | G43: 46217 | H43: 46217
B44: 6.1 | C44: Ejecución de protocolo FAT (según alcance definido) | D44: 1 | E44: Pendiente | F44: =IF($E44="N/A","",VLOOKUP($E44,AvanceTbl,2,FALSE())) -> 0 | K44: CMF
...

Sheet BUS_B
B2: SEGUIMIENTO DE INTEGRACIÓN — TABLERO BUS_B
B4: Proyecto: | F4: TAG: | G4: BUS_B | I4: Rev.:
B5: Fabricante: | F5: OC/Contrato: | I5: Actualizado:
B7: AVANCE GLOBAL DEL TABLERO | G7: =IFERROR(($D10*$F10+$D16*$F16+$D23*$F23+$D30*$F30+$D37*$F37+$D43*$F43+$D47*$F47+$D52*$F52)/($D10+$D16+$D23+$D30+$D37+$D43+$D47+$D52),0) -> 0.11842105
B9: # | C9: Hito / Sub-actividad | D9: Peso | E9: Estado | F9: Avance | G9: Plan Inicio | H9: Plan Fin | I9: Real Inicio | J9: Real Fin | K9: Responsable | L9: Observaciones
C10: 1. Armado de Tablero | D10: =SUMIF($E11:$E15,"<>N/A",$D11:$D15) -> 5 | F10: {=IFERROR(SUMPRODUCT(($E11:$E15<>"N/A")*$D11:$D15,IF($E11:$E15="N/A",0,$F11:$F15))/$D10,0)} -> 0.4 | G10: 46202 | H10: 46205
B11: 1.1 | C11: Recepción y verificación de envolvente (dimensiones, IP/IK, RAL) | D11: 1 | E11: Completado | F11: =IF($E11="N/A","",VLOOKUP($E11,AvanceTbl,2,FALSE())) -> 1 | K11: CSE
B12: 1.2 | C12: Ensamble de estructura y paneles del gabinete | D12: 1 | E12: Completado | F12: =IF($E12="N/A","",VLOOKUP($E12,AvanceTbl,2,FALSE())) -> 1 | K12: CMF
B13: 1.3 | C13: Montaje de perfilería DIN y placas de montaje | D13: 1 | E13: Pendiente | F13: =IF($E13="N/A","",VLOOKUP($E13,AvanceTbl,2,FALSE())) -> 0 | K13: CMF
B14: 1.4 | C14: Instalación de puertas, bisagras y cerraduras | D14: 1 | E14: Pendiente | F14: =IF($E14="N/A","",VLOOKUP($E14,AvanceTbl,2,FALSE())) -> 0 | K14: CMF
B15: 1.5 | C15: Fijación de canaletas y sistema de cableado | D15: 1 | E15: Pendiente | F15: =IF($E15="N/A","",VLOOKUP($E15,AvanceTbl,2,FALSE())) -> 0 | K15: CSE
C16: 2. Montaje de protecciones | D16: =SUMIF($E17:$E22,"<>N/A",$D17:$D22) -> 5 | F16: {=IFERROR(SUMPRODUCT(($E17:$E22<>"N/A")*$D17:$D22,IF($E17:$E22="N/A",0,$F17:$F22))/$D16,0)} -> 0.4 | G16: 46208 | H16: 46213
B17: 2.1 | C17: Verificación de aparatos vs. lista de materiales (marca/In/Icu) | D17: 1 | E17: Completado | F17: =IF($E17="N/A","",VLOOKUP($E17,AvanceTbl,2,FALSE())) -> 1 | K17: CSE
B18: 2.2 | C18: Montaje de interruptor principal | D18: 1 | E18: Completado | F18: =IF($E18="N/A","",VLOOKUP($E18,AvanceTbl,2,FALSE())) -> 1 | K18: CMF
B19: 2.3 | C19: Montaje de protecciones de derivación | D19: 1 | E19: Pendiente | F19: =IF($E19="N/A","",VLOOKUP($E19,AvanceTbl,2,FALSE())) -> 0 | K19: CMF
B20: 2.4 | C20: Montaje de diferenciales / protecciones auxiliares | D20: 1 | E20: N/A | F20: =IF($E20="N/A","",VLOOKUP($E20,AvanceTbl,2,FALSE())) | K20: CMF
B21: 2.5 | C21: Instalación de instrumentación (medidores, TC, relés) | D21: 1 | E21: Pendiente | F21: =IF($E21="N/A","",VLOOKUP($E21,AvanceTbl,2,FALSE())) -> 0 | K21: CMF
B22: 2.6 | C22: Fijación y torque de aparatos según layout | D22: 1 | E22: Pendiente | F22: =IF($E22="N/A","",VLOOKUP($E22,AvanceTbl,2,FALSE())) -> 0 | K22: CMF
C23: 3. Fabricación y montaje de barras | D23: =SUMIF($E24:$E29,"<>N/A",$D24:$D29) -> 6 | F23: {=IFERROR(SUMPRODUCT(($E24:$E29<>"N/A")*$D24:$D29,IF($E24:$E29="N/A",0,$F24:$F29))/$D23,0)} -> 0.083333333 | G23: 46208 | H23: 46213
B24: 3.1 | C24: Corte y conformado de barras (fases, N) | D24: 1 | E24: En proceso | F24: =IF($E24="N/A","",VLOOKUP($E24,AvanceTbl,2,FALSE())) -> 0.5 | K24: CMF
B25: 3.2 | C25: Perforado y tratamiento de superficie / aislamiento | D25: 1 | E25: Pendiente | F25: =IF($E25="N/A","",VLOOKUP($E25,AvanceTbl,2,FALSE())) -> 0 | K25: CMF
B26: 3.3 | C26: Montaje de aisladores y soportes de barra | D26: 1 | E26: Pendiente | F26: =IF($E26="N/A","",VLOOKUP($E26,AvanceTbl,2,FALSE())) -> 0 | K26: CMF
B27: 3.4 | C27: Instalación de barras principales con torque especificado | D27: 1 | E27: Pendiente | F27: =IF($E27="N/A","",VLOOKUP($E27,AvanceTbl,2,FALSE())) -> 0 | K27: CMF
B28: 3.5 | C28: Montaje de barra de tierra (PE) y neutro (N) | D28: 1 | E28: Pendiente | F28: =IF($E28="N/A","",VLOOKUP($E28,AvanceTbl,2,FALSE())) -> 0 | K28: CMF
B29: 3.6 | C29: Conexión de derivaciones a protecciones | D29: 1 | E29: Pendiente | F29: =IF($E29="N/A","",VLOOKUP($E29,AvanceTbl,2,FALSE())) -> 0 | K29: CMF
C30: 4. Alambrado del tablero | D30: =SUMIF($E31:$E36,"<>N/A",$D31:$D36) -> 6 | F30: {=IFERROR(SUMPRODUCT(($E31:$E36<>"N/A")*$D31:$D36,IF($E31:$E36="N/A",0,$F31:$F36))/$D30,0)} -> 0 | G30: 46212 | H30: 46213
B31: 4.1 | C31: Alambrado de circuito de fuerza | D31: 1 | E31: Pendiente | F31: =IF($E31="N/A","",VLOOKUP($E31,AvanceTbl,2,FALSE())) -> 0 | K31: CMF
B32: 4.2 | C32: Alambrado de circuito de control / mando | D32: 1 | E32: Pendiente | F32: =IF($E32="N/A","",VLOOKUP($E32,AvanceTbl,2,FALSE())) -> 0 | K32: CMF
B33: 4.3 | C33: Conexionado de instrumentación y señalización | D33: 1 | E33: Pendiente | F33: =IF($E33="N/A","",VLOOKUP($E33,AvanceTbl,2,FALSE())) -> 0 | K33: CMF
B34: 4.4 | C34: Montaje de punteras/terminales y apriete con torque | D34: 1 | E34: Pendiente | F34: =IF($E34="N/A","",VLOOKUP($E34,AvanceTbl,2,FALSE())) -> 0 | K34: CMF
B35: 4.5 | C35: Peinado y ordenamiento de mazos de cable | D35: 1 | E35: Pendiente | F35: =IF($E35="N/A","",VLOOKUP($E35,AvanceTbl,2,FALSE())) -> 0 | K35: CMF
B36: 4.6 | C36: Conexión de barra PE a partes metálicas accesibles | D36: 1 | E36: Pendiente | F36: =IF($E36="N/A","",VLOOKUP($E36,AvanceTbl,2,FALSE())) -> 0 | K36: CMF
C37: 5. Rotulación | D37: =SUMIF($E38:$E42,"<>N/A",$D38:$D42) -> 5 | F37: {=IFERROR(SUMPRODUCT(($E38:$E42<>"N/A")*$D38:$D42,IF($E38:$E42="N/A",0,$F38:$F42))/$D37,0)} -> 0 | G37: 46217 | H37: 46217
B38: 5.1 | C38: Etiquetado de conductores en ambos extremos | D38: 1 | E38: Pendiente | F38: =IF($E38="N/A","",VLOOKUP($E38,AvanceTbl,2,FALSE())) -> 0 | K38: CMF
B39: 5.2 | C39: Rotulado de aparatos y bornes según planos | D39: 1 | E39: Pendiente | F39: =IF($E39="N/A","",VLOOKUP($E39,AvanceTbl,2,FALSE())) -> 0 | K39: CMF
B40: 5.3 | C40: Instalación de placa de características (nameplate) | D40: 1 | E40: Pendiente | F40: =IF($E40="N/A","",VLOOKUP($E40,AvanceTbl,2,FALSE())) -> 0 | K40: CMF
B41: 5.4 | C41: Rótulos de advertencia y seguridad | D41: 1 | E41: Pendiente | F41: =IF($E41="N/A","",VLOOKUP($E41,AvanceTbl,2,FALSE())) -> 0 | K41: CMF
B42: 5.5 | C42: Verificación de coincidencia rótulos vs. esquema | D42: 1 | E42: Pendiente | F42: =IF($E42="N/A","",VLOOKUP($E42,AvanceTbl,2,FALSE())) -> 0 | K42: CSE
C43: 6. Pruebas FAT | D43: =SUMIF($E44:$E46,"<>N/A",$D44:$D46) -> 3 | F43: {=IFERROR(SUMPRODUCT(($E44:$E46<>"N/A")*$D44:$D46,IF($E44:$E46="N/A",0,$F44:$F46))/$D43,0)} -> 0 | G43: 46217 | H43: 46217
B44: 6.1 | C44: Ejecución de protocolo FAT (según alcance definido) | D44: 1 | E44: Pendiente | F44: =IF($E44="N/A","",VLOOKUP($E44,AvanceTbl,2,FALSE())) -> 0 | K44: CMF
...

Sheet CLIMA_A
B2: SEGUIMIENTO DE INTEGRACIÓN — TABLERO CLIMA_A
B4: Proyecto: | F4: TAG: | G4: CLIMA_A | I4: Rev.:
B5: Fabricante: | F5: OC/Contrato: | I5: Actualizado:
B7: AVANCE GLOBAL DEL TABLERO | G7: =IFERROR(($D10*$F10+$D16*$F16+$D23*$F23+$D30*$F30+$D37*$F37+$D43*$F43+$D47*$F47+$D52*$F52)/($D10+$D16+$D23+$D30+$D37+$D43+$D47+$D52),0) -> 0.20512821
B9: # | C9: Hito / Sub-actividad | D9: Peso | E9: Estado | F9: Avance | G9: Plan Inicio | H9: Plan Fin | I9: Real Inicio | J9: Real Fin | K9: Responsable | L9: Observaciones
C10: 1. Armado de Tablero | D10: =SUMIF($E11:$E15,"<>N/A",$D11:$D15) -> 5 | F10: {=IFERROR(SUMPRODUCT(($E11:$E15<>"N/A")*$D11:$D15,IF($E11:$E15="N/A",0,$F11:$F15))/$D10,0)} -> 0.5 | G10: 46202 | H10: 46205
B11: 1.1 | C11: Recepción y verificación de envolvente (dimensiones, IP/IK, RAL) | D11: 1 | E11: Completado | F11: =IF($E11="N/A","",VLOOKUP($E11,AvanceTbl,2,FALSE())) -> 1 | K11: CSE
B12: 1.2 | C12: Ensamble de estructura y paneles del gabinete | D12: 1 | E12: Completado | F12: =IF($E12="N/A","",VLOOKUP($E12,AvanceTbl,2,FALSE())) -> 1 | K12: CMF
B13: 1.3 | C13: Montaje de perfilería DIN y placas de montaje | D13: 1 | E13: En proceso | F13: =IF($E13="N/A","",VLOOKUP($E13,AvanceTbl,2,FALSE())) -> 0.5 | K13: CMF
B14: 1.4 | C14: Instalación de puertas, bisagras y cerraduras | D14: 1 | E14: Pendiente | F14: =IF($E14="N/A","",VLOOKUP($E14,AvanceTbl,2,FALSE())) -> 0 | K14: CMF
B15: 1.5 | C15: Fijación de canaletas y sistema de cableado | D15: 1 | E15: Pendiente | F15: =IF($E15="N/A","",VLOOKUP($E15,AvanceTbl,2,FALSE())) -> 0 | K15: CSE
C16: 2. Montaje de protecciones | D16: =SUMIF($E17:$E22,"<>N/A",$D17:$D22) -> 6 | F16: {=IFERROR(SUMPRODUCT(($E17:$E22<>"N/A")*$D17:$D22,IF($E17:$E22="N/A",0,$F17:$F22))/$D16,0)} -> 0.5 | G16: 46205 | H16: 46206
B17: 2.1 | C17: Verificación de aparatos vs. lista de materiales (marca/In/Icu) | D17: 1 | E17: Completado | F17: =IF($E17="N/A","",VLOOKUP($E17,AvanceTbl,2,FALSE())) -> 1 | K17: CSE
B18: 2.2 | C18: Montaje de interruptor principal | D18: 1 | E18: Completado | F18: =IF($E18="N/A","",VLOOKUP($E18,AvanceTbl,2,FALSE())) -> 1 | K18: CMF
B19: 2.3 | C19: Montaje de protecciones de derivación | D19: 1 | E19: En proceso | F19: =IF($E19="N/A","",VLOOKUP($E19,AvanceTbl,2,FALSE())) -> 0.5 | K19: CMF
B20: 2.4 | C20: Montaje de diferenciales / protecciones auxiliares | D20: 1 | E20: En proceso | F20: =IF($E20="N/A","",VLOOKUP($E20,AvanceTbl,2,FALSE())) -> 0.5 | K20: CMF
B21: 2.5 | C21: Instalación de instrumentación (medidores, TC, relés) | D21: 1 | E21: Pendiente | F21: =IF($E21="N/A","",VLOOKUP($E21,AvanceTbl,2,FALSE())) -> 0 | K21: CMF
B22: 2.6 | C22: Fijación y torque de aparatos según layout | D22: 1 | E22: Pendiente | F22: =IF($E22="N/A","",VLOOKUP($E22,AvanceTbl,2,FALSE())) -> 0 | K22: CMF
C23: 3. Fabricación y montaje de barras | D23: =SUMIF($E24:$E29,"<>N/A",$D24:$D29) -> 6 | F23: {=IFERROR(SUMPRODUCT(($E24:$E29<>"N/A")*$D24:$D29,IF($E24:$E29="N/A",0,$F24:$F29))/$D23,0)} -> 0.083333333 | G23: 46205 | H23: 46206
B24: 3.1 | C24: Corte y conformado de barras (fases, N) | D24: 1 | E24: En proceso | F24: =IF($E24="N/A","",VLOOKUP($E24,AvanceTbl,2,FALSE())) -> 0.5 | K24: CMF
B25: 3.2 | C25: Perforado y tratamiento de superficie / aislamiento | D25: 1 | E25: Pendiente | F25: =IF($E25="N/A","",VLOOKUP($E25,AvanceTbl,2,FALSE())) -> 0 | K25: CMF
B26: 3.3 | C26: Montaje de aisladores y soportes de barra | D26: 1 | E26: Pendiente | F26: =IF($E26="N/A","",VLOOKUP($E26,AvanceTbl,2,FALSE())) -> 0 | K26: CMF
B27: 3.4 | C27: Instalación de barras principales con torque especificado | D27: 1 | E27: Pendiente | F27: =IF($E27="N/A","",VLOOKUP($E27,AvanceTbl,2,FALSE())) -> 0 | K27: CMF
B28: 3.5 | C28: Montaje de barra de tierra (PE) y neutro (N) | D28: 1 | E28: Pendiente | F28: =IF($E28="N/A","",VLOOKUP($E28,AvanceTbl,2,FALSE())) -> 0 | K28: CMF
B29: 3.6 | C29: Conexión de derivaciones a protecciones | D29: 1 | E29: Pendiente | F29: =IF($E29="N/A","",VLOOKUP($E29,AvanceTbl,2,FALSE())) -> 0 | K29: CMF
C30: 4. Alambrado del tablero | D30: =SUMIF($E31:$E36,"<>N/A",$D31:$D36) -> 6 | F30: {=IFERROR(SUMPRODUCT(($E31:$E36<>"N/A")*$D31:$D36,IF($E31:$E36="N/A",0,$F31:$F36))/$D30,0)} -> 0.25 | G30: 46208 | H30: 46212
B31: 4.1 | C31: Alambrado de circuito de fuerza | D31: 1 | E31: En proceso | F31: =IF($E31="N/A","",VLOOKUP($E31,AvanceTbl,2,FALSE())) -> 0.5 | K31: CMF
B32: 4.2 | C32: Alambrado de circuito de control / mando | D32: 1 | E32: Pendiente | F32: =IF($E32="N/A","",VLOOKUP($E32,AvanceTbl,2,FALSE())) -> 0 | K32: CMF
B33: 4.3 | C33: Conexionado de instrumentación y señalización | D33: 1 | E33: Pendiente | F33: =IF($E33="N/A","",VLOOKUP($E33,AvanceTbl,2,FALSE())) -> 0 | K33: CMF
B34: 4.4 | C34: Montaje de punteras/terminales y apriete con torque | D34: 1 | E34: En proceso | F34: =IF($E34="N/A","",VLOOKUP($E34,AvanceTbl,2,FALSE())) -> 0.5 | K34: CMF
B35: 4.5 | C35: Peinado y ordenamiento de mazos de cable | D35: 1 | E35: En proceso | F35: =IF($E35="N/A","",VLOOKUP($E35,AvanceTbl,2,FALSE())) -> 0.5 | K35: CMF
B36: 4.6 | C36: Conexión de barra PE a partes metálicas accesibles | D36: 1 | E36: Pendiente | F36: =IF($E36="N/A","",VLOOKUP($E36,AvanceTbl,2,FALSE())) -> 0 | K36: CMF
C37: 5. Rotulación | D37: =SUMIF($E38:$E42,"<>N/A",$D38:$D42) -> 5 | F37: {=IFERROR(SUMPRODUCT(($E38:$E42<>"N/A")*$D38:$D42,IF($E38:$E42="N/A",0,$F38:$F42))/$D37,0)} -> 0.1 | G37: 46213 | H37: 46213
B38: 5.1 | C38: Etiquetado de conductores en ambos extremos | D38: 1 | E38: En proceso | F38: =IF($E38="N/A","",VLOOKUP($E38,AvanceTbl,2,FALSE())) -> 0.5 | K38: CMF
B39: 5.2 | C39: Rotulado de aparatos y bornes según planos | D39: 1 | E39: Pendiente | F39: =IF($E39="N/A","",VLOOKUP($E39,AvanceTbl,2,FALSE())) -> 0 | K39: CMF
B40: 5.3 | C40: Instalación de placa de características (nameplate) | D40: 1 | E40: Pendiente | F40: =IF($E40="N/A","",VLOOKUP($E40,AvanceTbl,2,FALSE())) -> 0 | K40: CMF
B41: 5.4 | C41: Rótulos de advertencia y seguridad | D41: 1 | E41: Pendiente | F41: =IF($E41="N/A","",VLOOKUP($E41,AvanceTbl,2,FALSE())) -> 0 | K41: CMF
B42: 5.5 | C42: Verificación de coincidencia rótulos vs. esquema | D42: 1 | E42: Pendiente | F42: =IF($E42="N/A","",VLOOKUP($E42,AvanceTbl,2,FALSE())) -> 0 | K42: CSE
C43: 6. Pruebas FAT | D43: =SUMIF($E44:$E46,"<>N/A",$D44:$D46) -> 3 | F43: {=IFERROR(SUMPRODUCT(($E44:$E46<>"N/A")*$D44:$D46,IF($E44:$E46="N/A",0,$F44:$F46))/$D43,0)} -> 0 | G43: 46213 | H43: 46213
B44: 6.1 | C44: Ejecución de protocolo FAT (según alcance definido) | D44: 1 | E44: Pendiente | F44: =IF($E44="N/A","",VLOOKUP($E44,AvanceTbl,2,FALSE())) -> 0 | K44: CMF
...

Sheet CLIMA_B
B2: SEGUIMIENTO DE INTEGRACIÓN — TABLERO CLIMA_B
B4: Proyecto: | F4: TAG: | G4: CLIMA_B | I4: Rev.:
B5: Fabricante: | F5: OC/Contrato: | I5: Actualizado:
B7: AVANCE GLOBAL DEL TABLERO | G7: =IFERROR(($D10*$F10+$D16*$F16+$D23*$F23+$D30*$F30+$D37*$F37+$D43*$F43+$D47*$F47+$D52*$F52)/($D10+$D16+$D23+$D30+$D37+$D43+$D47+$D52),0) -> 0.20512821
B9: # | C9: Hito / Sub-actividad | D9: Peso | E9: Estado | F9: Avance | G9: Plan Inicio | H9: Plan Fin | I9: Real Inicio | J9: Real Fin | K9: Responsable | L9: Observaciones
C10: 1. Armado de Tablero | D10: =SUMIF($E11:$E15,"<>N/A",$D11:$D15) -> 5 | F10: {=IFERROR(SUMPRODUCT(($E11:$E15<>"N/A")*$D11:$D15,IF($E11:$E15="N/A",0,$F11:$F15))/$D10,0)} -> 0.5 | G10: 46202 | H10: 46205
B11: 1.1 | C11: Recepción y verificación de envolvente (dimensiones, IP/IK, RAL) | D11: 1 | E11: Completado | F11: =IF($E11="N/A","",VLOOKUP($E11,AvanceTbl,2,FALSE())) -> 1 | K11: CSE
B12: 1.2 | C12: Ensamble de estructura y paneles del gabinete | D12: 1 | E12: Completado | F12: =IF($E12="N/A","",VLOOKUP($E12,AvanceTbl,2,FALSE())) -> 1 | K12: CMF
B13: 1.3 | C13: Montaje de perfilería DIN y placas de montaje | D13: 1 | E13: En proceso | F13: =IF($E13="N/A","",VLOOKUP($E13,AvanceTbl,2,FALSE())) -> 0.5 | K13: CMF
B14: 1.4 | C14: Instalación de puertas, bisagras y cerraduras | D14: 1 | E14: Pendiente | F14: =IF($E14="N/A","",VLOOKUP($E14,AvanceTbl,2,FALSE())) -> 0 | K14: CMF
B15: 1.5 | C15: Fijación de canaletas y sistema de cableado | D15: 1 | E15: Pendiente | F15: =IF($E15="N/A","",VLOOKUP($E15,AvanceTbl,2,FALSE())) -> 0 | K15: CSE
C16: 2. Montaje de protecciones | D16: =SUMIF($E17:$E22,"<>N/A",$D17:$D22) -> 6 | F16: {=IFERROR(SUMPRODUCT(($E17:$E22<>"N/A")*$D17:$D22,IF($E17:$E22="N/A",0,$F17:$F22))/$D16,0)} -> 0.5 | G16: 46205 | H16: 46206
B17: 2.1 | C17: Verificación de aparatos vs. lista de materiales (marca/In/Icu) | D17: 1 | E17: Completado | F17: =IF($E17="N/A","",VLOOKUP($E17,AvanceTbl,2,FALSE())) -> 1 | K17: CSE
B18: 2.2 | C18: Montaje de interruptor principal | D18: 1 | E18: Completado | F18: =IF($E18="N/A","",VLOOKUP($E18,AvanceTbl,2,FALSE())) -> 1 | K18: CMF
B19: 2.3 | C19: Montaje de protecciones de derivación | D19: 1 | E19: En proceso | F19: =IF($E19="N/A","",VLOOKUP($E19,AvanceTbl,2,FALSE())) -> 0.5 | K19: CMF
B20: 2.4 | C20: Montaje de diferenciales / protecciones auxiliares | D20: 1 | E20: En proceso | F20: =IF($E20="N/A","",VLOOKUP($E20,AvanceTbl,2,FALSE())) -> 0.5 | K20: CMF
B21: 2.5 | C21: Instalación de instrumentación (medidores, TC, relés) | D21: 1 | E21: Pendiente | F21: =IF($E21="N/A","",VLOOKUP($E21,AvanceTbl,2,FALSE())) -> 0 | K21: CMF
B22: 2.6 | C22: Fijación y torque de aparatos según layout | D22: 1 | E22: Pendiente | F22: =IF($E22="N/A","",VLOOKUP($E22,AvanceTbl,2,FALSE())) -> 0 | K22: CMF
C23: 3. Fabricación y montaje de barras | D23: =SUMIF($E24:$E29,"<>N/A",$D24:$D29) -> 6 | F23: {=IFERROR(SUMPRODUCT(($E24:$E29<>"N/A")*$D24:$D29,IF($E24:$E29="N/A",0,$F24:$F29))/$D23,0)} -> 0.083333333 | G23: 46205 | H23: 46206
B24: 3.1 | C24: Corte y conformado de barras (fases, N) | D24: 1 | E24: En proceso | F24: =IF($E24="N/A","",VLOOKUP($E24,AvanceTbl,2,FALSE())) -> 0.5 | K24: CMF
B25: 3.2 | C25: Perforado y tratamiento de superficie / aislamiento | D25: 1 | E25: Pendiente | F25: =IF($E25="N/A","",VLOOKUP($E25,AvanceTbl,2,FALSE())) -> 0 | K25: CMF
B26: 3.3 | C26: Montaje de aisladores y soportes de barra | D26: 1 | E26: Pendiente | F26: =IF($E26="N/A","",VLOOKUP($E26,AvanceTbl,2,FALSE())) -> 0 | K26: CMF
B27: 3.4 | C27: Instalación de barras principales con torque especificado | D27: 1 | E27: Pendiente | F27: =IF($E27="N/A","",VLOOKUP($E27,AvanceTbl,2,FALSE())) -> 0 | K27: CMF
B28: 3.5 | C28: Montaje de barra de tierra (PE) y neutro (N) | D28: 1 | E28: Pendiente | F28: =IF($E28="N/A","",VLOOKUP($E28,AvanceTbl,2,FALSE())) -> 0 | K28: CMF
B29: 3.6 | C29: Conexión de derivaciones a protecciones | D29: 1 | E29: Pendiente | F29: =IF($E29="N/A","",VLOOKUP($E29,AvanceTbl,2,FALSE())) -> 0 | K29: CMF
C30: 4. Alambrado del tablero | D30: =SUMIF($E31:$E36,"<>N/A",$D31:$D36) -> 6 | F30: {=IFERROR(SUMPRODUCT(($E31:$E36<>"N/A")*$D31:$D36,IF($E31:$E36="N/A",0,$F31:$F36))/$D30,0)} -> 0.25 | G30: 46208 | H30: 46212
B31: 4.1 | C31: Alambrado de circuito de fuerza | D31: 1 | E31: En proceso | F31: =IF($E31="N/A","",VLOOKUP($E31,AvanceTbl,2,FALSE())) -> 0.5 | K31: CMF
B32: 4.2 | C32: Alambrado de circuito de control / mando | D32: 1 | E32: Pendiente | F32: =IF($E32="N/A","",VLOOKUP($E32,AvanceTbl,2,FALSE())) -> 0 | K32: CMF
B33: 4.3 | C33: Conexionado de instrumentación y señalización | D33: 1 | E33: Pendiente | F33: =IF($E33="N/A","",VLOOKUP($E33,AvanceTbl,2,FALSE())) -> 0 | K33: CMF
B34: 4.4 | C34: Montaje de punteras/terminales y apriete con torque | D34: 1 | E34: En proceso | F34: =IF($E34="N/A","",VLOOKUP($E34,AvanceTbl,2,FALSE())) -> 0.5 | K34: CMF
B35: 4.5 | C35: Peinado y ordenamiento de mazos de cable | D35: 1 | E35: En proceso | F35: =IF($E35="N/A","",VLOOKUP($E35,AvanceTbl,2,FALSE())) -> 0.5 | K35: CMF
B36: 4.6 | C36: Conexión de barra PE a partes metálicas accesibles | D36: 1 | E36: Pendiente | F36: =IF($E36="N/A","",VLOOKUP($E36,AvanceTbl,2,FALSE())) -> 0 | K36: CMF
C37: 5. Rotulación | D37: =SUMIF($E38:$E42,"<>N/A",$D38:$D42) -> 5 | F37: {=IFERROR(SUMPRODUCT(($E38:$E42<>"N/A")*$D38:$D42,IF($E38:$E42="N/A",0,$F38:$F42))/$D37,0)} -> 0.1 | G37: 46213 | H37: 46213
B38: 5.1 | C38: Etiquetado de conductores en ambos extremos | D38: 1 | E38: En proceso | F38: =IF($E38="N/A","",VLOOKUP($E38,AvanceTbl,2,FALSE())) -> 0.5 | K38: CMF
B39: 5.2 | C39: Rotulado de aparatos y bornes según planos | D39: 1 | E39: Pendiente | F39: =IF($E39="N/A","",VLOOKUP($E39,AvanceTbl,2,FALSE())) -> 0 | K39: CMF
B40: 5.3 | C40: Instalación de placa de características (nameplate) | D40: 1 | E40: Pendiente | F40: =IF($E40="N/A","",VLOOKUP($E40,AvanceTbl,2,FALSE())) -> 0 | K40: CMF
B41: 5.4 | C41: Rótulos de advertencia y seguridad | D41: 1 | E41: Pendiente | F41: =IF($E41="N/A","",VLOOKUP($E41,AvanceTbl,2,FALSE())) -> 0 | K41: CMF
B42: 5.5 | C42: Verificación de coincidencia rótulos vs. esquema | D42: 1 | E42: Pendiente | F42: =IF($E42="N/A","",VLOOKUP($E42,AvanceTbl,2,FALSE())) -> 0 | K42: CSE
C43: 6. Pruebas FAT | D43: =SUMIF($E44:$E46,"<>N/A",$D44:$D46) -> 3 | F43: {=IFERROR(SUMPRODUCT(($E44:$E46<>"N/A")*$D44:$D46,IF($E44:$E46="N/A",0,$F44:$F46))/$D43,0)} -> 0 | G43: 46213 | H43: 46213
B44: 6.1 | C44: Ejecución de protocolo FAT (según alcance definido) | D44: 1 | E44: Pendiente | F44: =IF($E44="N/A","",VLOOKUP($E44,AvanceTbl,2,FALSE())) -> 0 | K44: CMF
...

Sheet NoConformidades
B2: REGISTRO DE NO CONFORMIDADES (NC)
B4: N° NC | C4: Fecha Detección | D4: Tablero | E4: Hito / Actividad | F4: Descripción de la NC | G4: Severidad | H4: Acción correctiva | I4: Estado | J4: Responsable | K4: Fecha Compromiso | L4: Fecha Cierre | M4: Evidencia/Ref. | N4: Días Abierta
B5: =IF(E5="","","NC-"&TEXT(ROW()-4,"000")) | N5: =IF(C5="","",IF(L5="",TODAY()-C5,L5-C5))
B6: =IF(E6="","","NC-"&TEXT(ROW()-4,"000")) | N6: =IF(C6="","",IF(L6="",TODAY()-C6,L6-C6))
B7: =IF(E7="","","NC-"&TEXT(ROW()-4,"000")) | N7: =IF(C7="","",IF(L7="",TODAY()-C7,L7-C7))
B8: =IF(E8="","","NC-"&TEXT(ROW()-4,"000")) | N8: =IF(C8="","",IF(L8="",TODAY()-C8,L8-C8))
B9: =IF(E9="","","NC-"&TEXT(ROW()-4,"000")) | N9: =IF(C9="","",IF(L9="",TODAY()-C9,L9-C9))
B10: =IF(E10="","","NC-"&TEXT(ROW()-4,"000")) | N10: =IF(C10="","",IF(L10="",TODAY()-C10,L10-C10))
B11: =IF(E11="","","NC-"&TEXT(ROW()-4,"000")) | N11: =IF(C11="","",IF(L11="",TODAY()-C11,L11-C11))
B12: =IF(E12="","","NC-"&TEXT(ROW()-4,"000")) | N12: =IF(C12="","",IF(L12="",TODAY()-C12,L12-C12))
B13: =IF(E13="","","NC-"&TEXT(ROW()-4,"000")) | N13: =IF(C13="","",IF(L13="",TODAY()-C13,L13-C13))
B14: =IF(E14="","","NC-"&TEXT(ROW()-4,"000")) | N14: =IF(C14="","",IF(L14="",TODAY()-C14,L14-C14))
B15: =IF(E15="","","NC-"&TEXT(ROW()-4,"000")) | N15: =IF(C15="","",IF(L15="",TODAY()-C15,L15-C15))
B16: =IF(E16="","","NC-"&TEXT(ROW()-4,"000")) | N16: =IF(C16="","",IF(L16="",TODAY()-C16,L16-C16))
... B34: =IF(E34="","","NC-"&TEXT(ROW()-4,"000")) | N34: =IF(C34="","",IF(L34="",TODAY()-C34,L34-C34))

Sheet ControlCambios
B2: CONTROL DE CAMBIOS
B4: N° Cambio | C4: Fecha | D4: Tablero | E4: Descripción del cambio | F4: Motivo / Justificación | G4: Impacto (plazo/costo/alcance) | H4: Estado | I4: Solicitante | J4: Aprobado por | K4: Fecha Aprob. | L4: Observaciones
B5: =IF(E5="","","CC-"&TEXT(ROW()-4,"000")) -> CC-001 | C5: 46223 | D5: CLIMA_A | E5: Reducción del largo total | F5: Espacio de instalación con poca holgura | G5: Bajo-Medio | H5: Propuesto | I5: PM / Cliente | L5: Informe RFC 001
B6: =IF(E6="","","CC-"&TEXT(ROW()-4,"000")) -> CC-002 | C6: 46223 | D6: CLIMA_B | E6: Reducción del largo total | F6: Espacio de instalación con poca holgura | G6: Bajo-Medio | H6: Propuesto | I6: PM / Cliente
B7: =IF(E7="","","CC-"&TEXT(ROW()-4,"000"))
B8: =IF(E8="","","CC-"&TEXT(ROW()-4,"000"))
B9: =IF(E9="","","CC-"&TEXT(ROW()-4,"000"))
B10: =IF(E10="","","CC-"&TEXT(ROW()-4,"000"))
B11: =IF(E11="","","CC-"&TEXT(ROW()-4,"000"))
B12: =IF(E12="","","CC-"&TEXT(ROW()-4,"000"))
B13: =IF(E13="","","CC-"&TEXT(ROW()-4,"000"))
B14: =IF(E14="","","CC-"&TEXT(ROW()-4,"000"))
B15: =IF(E15="","","CC-"&TEXT(ROW()-4,"000"))
B16: =IF(E16="","","CC-"&TEXT(ROW()-4,"000"))
B17: =IF(E17="","","CC-"&TEXT(ROW()-4,"000"))
B18: =IF(E18="","","CC-"&TEXT(ROW()-4,"000"))
... B29: =IF(E29="","","CC-"&TEXT(ROW()-4,"000"))

Sheet Config
B2: CONFIGURACIÓN
B4: Estados y valor de avance | J4: Tableros
B5: Estado | C5: Avance | J5: TP
B6: Pendiente | C6: 0 | J6: T_G2
B7: En proceso | C7: 0.5 | J7: BUS_A
B8: Completado | C8: 1 | J8: BUS_B
B9: N/A | J9: CLIMA_A
J10: CLIMA_B
B12: Severidad NC | E12: Estado NC | G12: Estado Cambio
B13: Menor | E13: Abierta | G13: Propuesto
B14: Mayor | E14: En análisis | G14: Aprobado
B15: Crítica | E15: En corrección | G15: Rechazado
E16: Cerrada | G16: Implementado
B19: Nota: no modificar los nombres de estado; las hojas los referencian por fórmula.
